Workbook

Sheet ipl_comprehensive_dataset
A1: event_name | B1: season | C1: match_number | D1: date | E1: city | F1: venue | G1: team1 | H1: team2 | I1: toss_winner | J1: toss_decision | K1: team1_runs | L1: team1_wickets | M1: team2_runs | N1: team2_wickets | O1: winner | P1: result_type | Q1: win_by_runs | R1: win_by_wickets | S1: player_of_match | T1: match_referee | U1: umpire1 | V1: umpire2 | W1: tv_umpire | X1: reserve_umpire | Y1: match_type | Z1: overs_limit | AA1: balls_per_over | AB1: gender | AC1: team_type | AD1: team1_players | AE1: team2_players
A2: Indian Premier League | B2: 2007/08 | C2: 1 | D2: 39556 | E2: Bangalore | F2: M Chinnaswamy Stadium | G2: Royal Challengers Bangalore | H2: Kolkata Knight Riders | I2: Royal Challengers Bangalore | J2: field | K2: 82 | L2: 10 | M2: 222 | N2: 3 | O2: Kolkata Knight Riders | P2: complete | Q2: 140 | R2: 0 | S2: BB McCullum | T2: J Srinath | U2: Asad Rauf | V2: RE Koertzen | W2: AM Saheba | X2: VN Kulkarni | Y2: T20 | Z2: 20 | AA2: 6 | AB2: male | AC2: club | AD2: R Dravid, W Jaffer, V Kohli, JH Kallis, CL White, MV Boucher, B Akhil, AA Noffke, P Kumar, Z Khan, SB Joshi | AE2: SC Ganguly, BB McCullum, RT Ponting, DJ Hussey, Mohammad Hafeez, LR Shukla, WP Saha, AB Agarkar, AB Dinda, M Kartik, I Sharma
A3: Indian Premier League | B3: 2007/08 | C3: 2 | D3: 39557 | E3: Chandigarh | F3: Punjab Cricket Association Stadium, Mohali | G3: Kings XI Punjab | H3: Chennai Super Kings | I3: Chennai Super Kings | J3: bat | K3: 207 | L3: 4 | M3: 240 | N3: 5 | O3: Chennai Super Kings | P3: complete | Q3: 33 | R3: 0 | S3: MEK Hussey | T3: S Venkataraghavan | U3: MR Benson | V3: SL Shastri | W3: RB Tiffin | X3: MSS Ranawat | Y3: T20 | Z3: 20 | AA3: 6 | AB3: male | AC3: club | AD3: K Goel, JR Hopes, KC Sangakkara, Yuvraj Singh, SM Katich, IK Pathan, P Dharmani, B Lee, PP Chawla, WA Mota, S Sreesanth | AE3: PA Patel, ML Hayden, MEK Hussey, MS Dhoni, SK Raina, JDP Oram, S Badrinath, Joginder Sharma, P Amarnath, MS Gony, M Muralitharan
A4: Indian Premier League | B4: 2007/08 | C4: 3 | D4: 39557 | E4: Delhi | F4: Feroz Shah Kotla | G4: Delhi Daredevils | H4: Rajasthan Royals | I4: Rajasthan Royals | J4: bat | K4: 132 | L4: 1 | M4: 129 | N4: 8 | O4: Delhi Daredevils | P4: complete | Q4: 0 | R4: 9 | S4: MF Maharoof | T4: GR Viswanath | U4: Aleem Dar | V4: GA Pratapkumar | W4: IL Howell | X4: Unknown | Y4: T20 | Z4: 20 | AA4: 6 | AB4: male | AC4: club | AD4: G Gambhir, V Sehwag, S Dhawan, MK Tiwary, KD Karthik, R Bhatia, M Manhas, DL Vettori, MF Maharoof, B Geeves, GD McGrath | AE4: T Kohli, YK Pathan, SR Watson, M Kaif, DS Lehmann, RA Jadeja, M Rawat, D Salunkhe, SK Warne, SK Trivedi, MM Patel
A5: Indian Premier League | B5: 2007/08 | C5: 4 | D5: 39558 | E5: Kolkata | F5: Eden Gardens | G5: Kolkata Knight Riders | H5: Deccan Chargers | I5: Deccan Chargers | J5: bat | K5: 112 | L5: 5 | M5: 110 | N5: 10 | O5: Kolkata Knight Riders | P5: complete | Q5: 0 | R5: 5 | S5: DJ Hussey | T5: FM Engineer | U5: BF Bowden | V5: K Hariharan | W5: Asad Rauf | X5: F Gomes | Y5: T20 | Z5: 20 | AA5: 6 | AB5: male | AC5: club | AD5: WP Saha, BB McCullum, RT Ponting, SC Ganguly, DJ Hussey, Mohammad Hafeez, LR Shukla, AB Agarkar, AB Dinda, M Kartik, I Sharma | AE5: AC Gilchrist, Y Venugopal Rao, VVS Laxman, A Symonds, RG Sharma, SB Styris, AS Yadav, SB Bangar, WPUJC Vaas, RP Singh, PP Ojha
A6: Indian Premier League | B6: 2007/08 | C6: 5 | D6: 39558 | E6: Mumbai | F6: Wankhede Stadium | G6: Mumbai Indians | H6: Royal Challengers Bangalore | I6: Mumbai Indians | J6: bat | K6: 165 | L6: 7 | M6: 166 | N6: 5 | O6: Royal Challengers Bangalore | P6: complete | Q6: 0 | R6: 5 | S6: MV Boucher | T6: J Srinath | U6: SJ Davis | V6: DJ Harper | W6: AV Jayaprakash | X6: SN Bandekar | Y6: T20 | Z6: 20 | AA6: 6 | AB6: male | AC6: club | AD6: L Ronchi, ST Jayasuriya, DJ Thornely, RV Uthappa, PR Shah, AM Nayar, SM Pollock, Harbhajan Singh, MA Khote, A Nehra, DS Kulkarni | AE6: S Chanderpaul, R Dravid, LRPL Taylor, JH Kallis, V Kohli, MV Boucher, B Akhil, P Kumar, Z Khan, SB Joshi, R Vinay Kumar
A7: Indian Premier League | B7: 2007/08 | C7: 6 | D7: 39559 | E7: Jaipur | F7: Sawai Mansingh Stadium | G7: Rajasthan Royals | H7: Kings XI Punjab | I7: Kings XI Punjab | J7: bat | K7: 168 | L7: 4 | M7: 166 | N7: 8 | O7: Rajasthan Royals | P7: complete | Q7: 0 | R7: 6 | S7: SR Watson | T7: S Venkataraghavan | U7: Aleem Dar | V7: RB Tiffin | W7: I Shivram | X7: MSS Ranawat | Y7: T20 | Z7: 20 | AA7: 6 | AB7: male | AC7: club | AD7: M Kaif, Kamran Akmal, YK Pathan, SR Watson, DS Lehmann, RA Jadeja, Pankaj Singh, D Salunkhe, SK Warne, SK Trivedi, MM Patel | AE7: K Goel, JR Hopes, KC Sangakkara, DPMD Jayawardene, Yuvraj Singh, IK Pathan, S Sohal, B Lee, PP Chawla, WA Mota, S Sreesanth
A8: Indian Premier League | B8: 2007/08 | C8: 7 | D8: 39560 | E8: Hyderabad | F8: Rajiv Gandhi International Stadium, Uppal | G8: Deccan Chargers | H8: Delhi Daredevils | I8: Deccan Chargers | J8: bat | K8: 142 | L8: 8 | M8: 143 | N8: 1 | O8: Delhi Daredevils | P8: complete | Q8: 0 | R8: 9 | S8: V Sehwag | T8: Talat Ali | U8: IL Howell | V8: AM Saheba | W8: MR Benson | X8: C Shamshuddin | Y8: T20 | Z8: 20 | AA8: 6 | AB8: male | AC8: club | AD8: AC Gilchrist, Y Venugopal Rao, VVS Laxman, A Symonds, RG Sharma, Shahid Afridi, SB Bangar, AS Yadav, WPUJC Vaas, RP Singh, PP Ojha | AE8: G Gambhir, V Sehwag, S Dhawan, Shoaib Malik, KD Karthik, MK Tiwary, R Bhatia, MF Maharoof, Mohammad Asif, VY Mahesh, GD McGrath
A9: Indian Premier League | B9: 2007/08 | C9: 8 | D9: 39561 | E9: Chennai | F9: MA Chidambaram Stadium, Chepauk | G9: Chennai Super Kings | H9: Mumbai Indians | I9: Mumbai Indians | J9: field | K9: 208 | L9: 5 | M9: 202 | N9: 7 | O9: Chennai Super Kings | P9: complete | Q9: 6 | R9: 0 | S9: ML Hayden | T9: FM Engineer | U9: DJ Harper | V9: GA Pratapkumar | W9: BF Bowden | X9: S Ravi | Y9: T20 | Z9: 20 | AA9: 6 | AB9: male | AC9: club | AD9: PA Patel, ML Hayden, MEK Hussey, SK Raina, MS Dhoni, JDP Oram, S Badrinath, Joginder Sharma, P Amarnath, MS Gony, M Muralitharan | AE9: L Ronchi, ST Jayasuriya, RV Uthappa, SM Pollock, DJ Bravo, AM Nayar, MA Khote, Harbhajan Singh, A Nehra, VS Yeligati, DS Kulkarni
A10: Indian Premier League | B10: 2007/08 | C10: 9 | D10: 39562 | E10: Hyderabad | F10: Rajiv Gandhi International Stadium, Uppal | G10: Deccan Chargers | H10: Rajasthan Royals | I10: Rajasthan Royals | J10: field | K10: 214 | L10: 5 | M10: 217 | N10: 7 | O10: Rajasthan Royals | P10: complete | Q10: 0 | R10: 3 | S10: YK Pathan | T10: S Venkataraghavan | U10: Asad Rauf | V10: MR Benson | W10: SL Shastri | X10: C Shamshuddin | Y10: T20 | Z10: 20 | AA10: 6 | AB10: male | AC10: club | AD10: AC Gilchrist, VVS Laxman, Shahid Afridi, A Symonds, RG Sharma, AS Yadav, SB Bangar, WPUJC Vaas, RP Singh, PP Ojha, D Kalyankrishna | AE10: Kamran Akmal, GC Smith, YK Pathan, SR Watson, M Kaif, RA Jadeja, SK Warne, D Salunkhe, Pankaj Singh, SK Trivedi, MM Patel
A11: Indian Premier League | B11: 2007/08 | C11: 10 | D11: 39563 | E11: Chandigarh | F11: Punjab Cricket Association Stadium, Mohali | G11: Kings XI Punjab | H11: Mumbai Indians | I11: Mumbai Indians | J11: field | K11: 182 | L11: 10 | M11: 116 | N11: 9 | O11: Kings XI Punjab | P11: complete | Q11: 66 | R11: 0 | S11: KC Sangakkara | T11: FM Engineer | U11: Aleem Dar | V11: AM Saheba | W11: RE Koertzen | X11: HS Sekhon | Y11: T20 | Z11: 20 | AA11: 6 | AB11: male | AC11: club | AD11: K Goel, IK Pathan, KC Sangakkara, Yuvraj Singh, RR Sarwan, DPMD Jayawardene, S Sohal, B Lee, PP Chawla, S Sreesanth, VRV Singh | AE11: L Ronchi, ST Jayasuriya, RV Uthappa, DJ Bravo, SS Tiwary, SM Pollock, AM Nayar, Harbhajan Singh, MA Khote, DS Kulkarni, A Nehra
A12: Indian Premier League | B12: 2007/08 | C12: 11 | D12: 39564 | E12: Chennai | F12: MA Chidambaram Stadium, Chepauk | G12: Chennai Super Kings | H12: Kolkata Knight Riders | I12: Kolkata Knight Riders | J12: bat | K12: 152 | L12: 1 | M12: 147 | N12: 9 | O12: Chennai Super Kings | P12: complete | Q12: 0 | R12: 9 | S12: JDP Oram | T12: Talat Ali | U12: BF Bowden | V12: AV Jayaprakash | W12: SJ Davis | X12: S Ravi | Y12: T20 | Z12: 20 | AA12: 6 | AB12: male | AC12: club | AD12: PA Patel, ML Hayden, MS Dhoni, MEK Hussey, S Badrinath, SK Raina, JDP Oram, Joginder Sharma, P Amarnath, MS Gony, M Muralitharan | AE12: SC Ganguly, BB McCullum, RT Ponting, WP Saha, DJ Hussey, Mohammad Hafeez, LR Shukla, AB Agarkar, M Kartik, I Sharma, AB Dinda
A13: Indian Premier League | B13: 2007/08 | C13: 12 | D13: 39564 | E13: Bangalore | F13: M Chinnaswamy Stadium | G13: Royal Challengers Bangalore | H13: Rajasthan Royals | I13: Rajasthan Royals | J13: field | K13: 135 | L13: 8 | M13: 138 | N13: 3 | O13: Rajasthan Royals | P13: complete | Q13: 0 | R13: 7 | S13: SR Watson | T13: J Srinath | U13: MR Benson | V13: IL Howell | W13: GA Pratapkumar | X13: SK Tarapore | Y13: T20 | Z13: 20 | AA13: 6 | AB13: male | AC13: club | AD13: S Chanderpaul, R Dravid, LRPL Taylor, JH Kallis, V Kohli, MV Boucher, P Kumar, SB Joshi, Z Khan, R Vinay Kumar, A Kumble | AE13: GC Smith, M Rawat, YK Pathan, SR Watson, M Kaif, RA Jadeja, D Salunkhe, SK Warne, Sohail Tanvir, SK Trivedi, MM Patel
... A56: Indian Premier League | B56: 2007/08 | C56: 56 | D56: 39596 | E56: Chandigarh | F56: Punjab Cricket Association Stadium, Mohali | G56: Kings XI Punjab | H56: Rajasthan Royals | I56: Rajasthan Royals | J56: field | K56: 221 | L56: 3 | M56: 180 | N56: 7 | O56: Kings XI Punjab | P56: complete | Q56: 41 | R56: 0 | S56: SE Marsh | T56: S Venkataraghavan | U56: SJ Davis | V56: K Hariharan | W56: DJ Harper | X56: MS Mahal | Y56: T20 | Z56: 20 | AA56: 6 | AB56: male | AC56: club | AD56: SE Marsh, JR Hopes, Yuvraj Singh, LA Pomersbach, KC Sangakkara, RR Powar, PP Chawla, IK Pathan, VRV Singh, S Sreesanth, WA Mota | AE56: M Kaif, NK Patel, Younis Khan, SR Watson, YK Pathan, Kamran Akmal, M Rawat, D Salunkhe, Pankaj Singh, SK Trivedi, MM Patel
A57: Indian Premier League | B57: 2007/08 | C57: N/A | D57: 39598 | E57: Mumbai | F57: Wankhede Stadium | G57: Delhi Daredevils | H57: Rajasthan Royals | I57: Delhi Daredevils | J57: field | K57: 87 | L57: 10 | M57: 192 | N57: 9 | O57: Rajasthan Royals | P57: complete | Q57: 105 | R57: 0 | S57: SR Watson | T57: J Srinath | U57: BF Bowden | V57: RE Koertzen | W57: BR Doctrove | X57: Unknown | Y57: T20 | Z57: 20 | AA57: 6 | AB57: male | AC57: club | AD57: G Gambhir, V Sehwag, S Dhawan, MK Tiwary, TM Dilshan, KD Karthik, MF Maharoof, A Mishra, VY Mahesh, Mohammad Asif, GD McGrath | AE57: GC Smith, SA Asnodkar, Sohail Tanvir, SR Watson, M Kaif, YK Pathan, RA Jadeja, SK Warne, M Rawat, MM Patel, SK Trivedi
A58: Indian Premier League | B58: 2007/08 | C58: N/A | D58: 39599 | E58: Mumbai | F58: Wankhede Stadium | G58: Chennai Super Kings | H58: Kings XI Punjab | I58: Kings XI Punjab | J58: bat | K58: 116 | L58: 1 | M58: 112 | N58: 8 | O58: Chennai Super Kings | P58: complete | Q58: 0 | R58: 9 | S58: M Ntini | T58: S Venkataraghavan | U58: Asad Rauf | V58: DJ Harper | W58: K Hariharan | X58: Unknown | Y58: T20 | Z58: 20 | AA58: 6 | AB58: male | AC58: club | AD58: PA Patel, S Vidyut, SK Raina, MS Dhoni, CK Kapugedera, S Badrinath, JA Morkel, MS Gony, L Balaji, M Muralitharan, M Ntini | AE58: SE Marsh, JR Hopes, KC Sangakkara, Yuvraj Singh, DPMD Jayawardene, IK Pathan, WA Mota, PP Chawla, RR Powar, S Sreesanth, VRV Singh
A59: Indian Premier League | B59: 2007/08 | C59: N/A | D59: 39600 | E59: Mumbai | F59: Dr DY Patil Sports Academy | G59: Chennai Super Kings | H59: Rajasthan Royals | I59: Rajasthan Royals | J59: field | K59: 163 | L59: 5 | M59: 164 | N59: 7 | O59: Rajasthan Royals | P59: complete | Q59: 0 | R59: 3 | S59: YK Pathan | T59: J Srinath | U59: BF Bowden | V59: RE Koertzen | W59: DJ Harper | X59: MR Singh | Y59: T20 | Z59: 20 | AA59: 6 | AB59: male | AC59: club | AD59: PA Patel, S Vidyut, SK Raina, JA Morkel, MS Dhoni, CK Kapugedera, S Badrinath, MS Gony, L Balaji, M Muralitharan, M Ntini | AE59: NK Patel, SA Asnodkar, Kamran Akmal, SR Watson, YK Pathan, M Kaif, RA Jadeja, SK Warne, Sohail Tanvir, SK Trivedi, MM Patel
A60: Indian Premier League | B60: 2009 | C60: 1 | D60: 39921 | E60: Cape Town | F60: Newlands | G60: Chennai Super Kings | H60: Mumbai Indians | I60: Chennai Super Kings | J60: field | K60: 146 | L60: 7 | M60: 165 | N60: 7 | O60: Mumbai Indians | P60: complete | Q60: 19 | R60: 0 | S60: SR Tendulkar | T60: GR Viswanath | U60: BR Doctrove | V60: K Hariharan | W60: RB Tiffin | X60: EC Hendrikse | Y60: T20 | Z60: 20 | AA60: 6 | AB60: male | AC60: club | AD60: PA Patel, ML Hayden, SK Raina, A Flintoff, MS Dhoni, JDP Oram, S Badrinath, Joginder Sharma, T Thushara, MS Gony, R Ashwin | AE60: ST Jayasuriya, SR Tendulkar, S Dhawan, JP Duminy, DJ Bravo, AM Nayar, Harbhajan Singh, Z Khan, PR Shah, SL Malinga, RR Raje
A61: Indian Premier League | B61: 2009 | C61: 2 | D61: 39921 | E61: Cape Town | F61: Newlands | G61: Royal Challengers Bangalore | H61: Rajasthan Royals | I61: Royal Challengers Bangalore | J61: bat | K61: 133 | L61: 8 | M61: 58 | N61: 10 | O61: Royal Challengers Bangalore | P61: complete | Q61: 75 | R61: 0 | S61: R Dravid | T61: GR Viswanath | U61: BR Doctrove | V61: RB Tiffin | W61: K Hariharan | X61: EC Hendrikse | Y61: T20 | Z61: 20 | AA61: 6 | AB61: male | AC61: club | AD61: JD Ryder, RV Uthappa, LRPL Taylor, KP Pietersen, R Dravid, V Kohli, B Akhil, P Kumar, R Vinay Kumar, DW Steyn, A Kumble | AE61: GC Smith, SA Asnodkar, NK Patel, T Henderson, YK Pathan, AD Mascarenhas, RA Jadeja, SK Warne, M Rawat, MM Patel, Kamran Khan
A62: Indian Premier League | B62: 2009 | C62: 3 | D62: 39922 | E62: Cape Town | F62: Newlands | G62: Delhi Daredevils | H62: Kings XI Punjab | I62: Delhi Daredevils | J62: field | K62: 58 | L62: 0 | M62: 104 | N62: 7 | O62: Delhi Daredevils | P62: complete | Q62: 0 | R62: 10 | S62: DL Vettori | T62: Yashpal Sharma | U62: MR Benson | V62: SD Ranade | W62: AL Hill | X62: MW Brown | Y62: T20 | Z62: 20 | AA62: 6 | AB62: male | AC62: club | AD62: G Gambhir, V Sehwag, TM Dilshan, AB de Villiers, MK Tiwary, KD Karthik, DP Nannes, DL Vettori, VY Mahesh, AM Salvi, PJ Sangwan | AE62: RS Bopara, K Goel, Yuvraj Singh, KC Sangakkara, DPMD Jayawardene, IK Pathan, PP Chawla, T Kohli, VS Malik, VRV Singh, YA Abdulla
A63: Indian Premier League | B63: 2009 | C63: 4 | D63: 39922 | E63: Cape Town | F63: Newlands | G63: Deccan Chargers | H63: Kolkata Knight Riders | I63: Kolkata Knight Riders | J63: bat | K63: 104 | L63: 2 | M63: 101 | N63: 10 | O63: Deccan Chargers | P63: complete | Q63: 0 | R63: 8 | S63: RP Singh | T63: Yashpal Sharma | U63: MR Benson | V63: BR Doctrove | W63: SD Ranade | X63: MW Brown | Y63: T20 | Z63: 20 | AA63: 6 | AB63: male | AC63: club | AD63: AC Gilchrist, HH Gibbs, VVS Laxman, RG Sharma, SB Styris, Y Venugopal Rao, Harmeet Singh, PP Ojha, RP Singh, DB Ravi Teja, FH Edwards | AE63: BB McCullum, CH Gayle, SC Ganguly, BJ Hodge, A Chopra, LR Shukla, MC Henriques, AB Agarkar, M Kartik, I Sharma, AB Dinda
A64: Indian Premier League | B64: 2009 | C64: 5 | D64: 39923 | E64: Port Elizabeth | F64: St George's Park | G64: Royal Challengers Bangalore | H64: Chennai Super Kings | I64: Chennai Super Kings | J64: bat | K64: 87 | L64: 10 | M64: 179 | N64: 5 | O64: Chennai Super Kings | P64: complete | Q64: 92 | R64: 0 | S64: M Muralitharan | T64: GR Viswanath | U64: BG Jerling | V64: SJA Taufel | W64: RB Tiffin | X64: S George | Y64: T20 | Z64: 20 | AA64: 6 | AB64: male | AC64: club | AD64: P Kumar, RV Uthappa, JH Kallis, LRPL Taylor, KP Pietersen, R Dravid, V Kohli, R Bishnoi, R Vinay Kumar, DW Steyn, A Kumble | AE64: PA Patel, ML Hayden, SK Raina, MS Dhoni, A Flintoff, JA Morkel, S Badrinath, Joginder Sharma, L Balaji, MS Gony, M Muralitharan
A65: Indian Premier League | B65: 2009 | C65: 6 | D65: 39924 | E65: Durban | F65: Kingsmead | G65: Kings XI Punjab | H65: Kolkata Knight Riders | I65: Kolkata Knight Riders | J65: field | K65: 158 | L65: 6 | M65: 79 | N65: 1 | O65: Kolkata Knight Riders | P65: complete | Q65: 11 | R65: 0 | S65: CH Gayle | T65: D Govindjee | U65: DJ Harper | V65: SD Ranade | W65: TH Wijewardene | X65: EC Hendrikse | Y65: T20 | Z65: 20 | AA65: 6 | AB65: male | AC65: club | AD65: RS Bopara, K Goel, IK Pathan, KC Sangakkara, Yuvraj Singh, DPMD Jayawardene, T Kohli, PP Chawla, VS Malik, VRV Singh, YA Abdulla | AE65: BB McCullum, CH Gayle, BJ Hodge, SC Ganguly, Yashpal Singh, A Chopra, MC Henriques, LR Shukla, I Sharma, M Kartik, AB Dinda
A66: Indian Premier League | B66: 2009 | C66: 8 | D66: 39925 | E66: Cape Town | F66: Newlands | G66: Royal Challengers Bangalore | H66: Deccan Chargers | I66: Deccan Chargers | J66: bat | K66: 160 | L66: 8 | M66: 184 | N66: 6 | O66: Deccan Chargers | P66: complete | Q66: 24 | R66: 0 | S66: AC Gilchrist | T66: Yashpal Sharma | U66: M Erasmus | V66: AM Saheba | W66: MR Benson | X66: Unknown | Y66: T20 | Z66: 20 | AA66: 6 | AB66: male | AC66: club | AD66: JD Ryder, RV Uthappa, JH Kallis, KP Pietersen, R Dravid, V Kohli, R Bishnoi, KV Sharma, P Kumar, A Kumble, DW Steyn | AE66: AC Gilchrist, HH Gibbs, VVS Laxman, RG Sharma, SB Styris, Y Venugopal Rao, DB Ravi Teja, FH Edwards, Harmeet Singh, PP Ojha, RP Singh
A67: Indian Premier League | B67: 2009 | C67: 9 | D67: 39926 | E67: Durban | F67: Kingsmead | G67: Chennai Super Kings | H67: Delhi Daredevils | I67: Delhi Daredevils | J67: bat | K67: 180 | L67: 9 | M67: 189 | N67: 5 | O67: Delhi Daredevils | P67: complete | Q67: 9 | R67: 0 | S67: AB de Villiers | T67: D Govindjee | U67: BR Doctrove | V67: SJA Taufel | W67: SD Ranade | X67: ZTA Ndamane | Y67: T20 | Z67: 20 | AA67: 6 | AB67: male | AC67: club | AD67: PA Patel, ML Hayden, SK Raina, MS Dhoni, A Flintoff, JA Morkel, S Badrinath, MS Gony, Joginder Sharma, L Balaji, M Muralitharan | AE67: G Gambhir, V Sehwag, AB de Villiers, TM Dilshan, KD Karthik, MK Tiwary, DL Vettori, DP Nannes, AM Salvi, PJ Sangwan, A Nehra
A68: Indian Premier League | B68: 2009 | C68: 10 | D68: 39926 | E68: Cape Town | F68: Newlands | G68: Kolkata Knight Riders | H68: Rajasthan Royals | I68: Kolkata Knight Riders | J68: field | K68: 165 | L68: 9 | M68: 168 | N68: 6 | O68: None | P68: tie | Q68: 0 | R68: 0 | S68: YK Pathan | T68: GR Viswanath | U68: MR Benson | V68: M Erasmus | W68: AM Saheba | X68: EC Hendrikse | Y68: T20 | Z68: 20 | AA68: 6 | AB68: male | AC68: club | AD68: CH Gayle, BB McCullum, LR Shukla, BJ Hodge, SC Ganguly, SB Bangar, Yashpal Singh, AB Agarkar, I Sharma, BAW Mendis, Anureet Singh | AE68: GC Smith, PC Valthaty, RJ Quiney, YK Pathan, RA Jadeja, AD Mascarenhas, AS Raut, SK Warne, M Rawat, MM Patel, Kamran Khan
A69: Indian Premier League | B69: 2009 | C69: 11 | D69: 39927 | E69: Durban | F69: Kingsmead | G69: Royal Challengers Bangalore | H69: Kings XI Punjab | I69: Royal Challengers Bangalore | J69: bat | K69: 168 | L69: 9 | M69: 173 | N69: 3 | O69: Kings XI Punjab | P69: complete | Q69: 0 | R69: 7 | S69: RS Bopara | T69: D Govindjee | U69: BR Doctrove | V69: TH Wijewardene | W69: SJA Taufel | X69: ZTA Ndamane | Y69: T20 | Z69: 20 | AA69: 6 | AB69: male | AC69: club | AD69: JD Ryder, RV Uthappa, JH Kallis, KP Pietersen, R Dravid, LRPL Taylor, V Kohli, P Kumar, R Vinay Kumar, Pankaj Singh, A Kumble | AE69: RS Bopara, K Goel, KC Sangakkara, Yuvraj Singh, DPMD Jayawardene, IK Pathan, WA Mota, PP Chawla, VRV Singh, RR Bose, YA Abdulla
A70: Indian Premier League | B70: 2009 | C70: 12 | D70: 39928 | E70: Durban | F70: Kingsmead | G70: Deccan Chargers | H70: Mumbai Indians | I70: Deccan Chargers | J70: bat | K70: 168 | L70: 9 | M70: 156 | N70: 7 | O70: Deccan Chargers | P70: complete | Q70: 12 | R70: 0 | S70: PP Ojha | T70: D Govindjee | U70: HDPK Dharmasena | V70: SJA Taufel | W70: SD Ranade | X70: ZTA Ndamane | Y70: T20 | Z70: 20 | AA70: 6 | AB70: male | AC70: club | AD70: AC Gilchrist, HH Gibbs, DR Smith, RG Sharma, VVS Laxman, Y Venugopal Rao, DB Ravi Teja, RP Singh, FH Edwards, PP Ojha, Harmeet Singh | AE70: ST Jayasuriya, SR Tendulkar, JP Duminy, S Dhawan, DJ Bravo, AM Nayar, Harbhajan Singh, Z Khan, PR Shah, SL Malinga, DS Kulkarni
A71: Indian Premier League | B71: 2009 | C71: 14 | D71: 39929 | E71: Port Elizabeth | F71: St George's Park | G71: Royal Challengers Bangalore | H71: Delhi Daredevils | I71: Royal Challengers Bangalore | J71: bat | K71: 149 | L71: 7 | M71: 150 | N71: 4 | O71: Delhi Daredevils | P71: complete | Q71: 0 | R71: 6 | S71: TM Dilshan | T71: Yashpal Sharma | U71: S Asnani | V71: BG Jerling | W71: BR Doctrove | X71: S George | Y71: T20 | Z71: 20 | AA71: 6 | AB71: male | AC71: club | AD71: JH Kallis, RV Uthappa, KP Pietersen, LRPL Taylor, V Kohli, MV Boucher, B Akhil, R Vinay Kumar, Pankaj Singh, A Kumble, KP Appanna | AE71: G Gambhir, V Sehwag, TM Dilshan, AB de Villiers, KD Karthik, M Manhas, A Mishra, DL Vettori, DP Nannes, PJ Sangwan, A Nehra
... A113: Indian Premier League | B113: 2009 | C113: 56 | D113: 39954 | E113: Centurion | F113: SuperSport Park | G113: Royal Challengers Bangalore | H113: Deccan Chargers | I113: Royal Challengers Bangalore | J113: bat | K113: 170 | L113: 4 | M113: 158 | N113: 6 | O113: Royal Challengers Bangalore | P113: complete | Q113: 12 | R113: 0 | S113: MK Pandey | T113: S Venkataraghavan | U113: IL Howell | V113: S Ravi | W113: SK Tarapore | X113: MW Brown | Y113: T20 | Z113: 20 | AA113: 6 | AB113: male | AC113: club | AD113: JH Kallis, MK Pandey, RE van der Merwe, R Dravid, LRPL Taylor, V Kohli, RV Uthappa, MV Boucher, P Kumar, B Akhil, A Kumble | AE113: AC Gilchrist, HH Gibbs, TL Suman, A Symonds, RG Sharma, Y Venugopal Rao, AA Bilakhia, RJ Harris, Jaskaran Singh, RP Singh, PP Ojha
A114: Indian Premier League | B114: 2009 | C114: N/A | D114: 39955 | E114: Centurion | F114: SuperSport Park | G114: Delhi Daredevils | H114: Deccan Chargers | I114: Deccan Chargers | J114: field | K114: 153 | L114: 8 | M114: 154 | N114: 4 | O114: Deccan Chargers | P114: complete | Q114: 0 | R114: 6 | S114: AC Gilchrist | T114: S Venkataraghavan | U114: BR Doctrove | V114: DJ Harper | W114: RE Koertzen | X114: JD Cloete | Y114: T20 | Z114: 20 | AA114: 6 | AB114: male | AC114: club | AD114: G Gambhir, DA Warner, V Sehwag, TM Dilshan, AB de Villiers, KD Karthik, R Bhatia, A Mishra, PJ Sangwan, DP Nannes, A Nehra | AE114: AC Gilchrist, HH Gibbs, AA Bilakhia, TL Suman, A Symonds, RG Sharma, Y Venugopal Rao, RJ Harris, PP Ojha, Harmeet Singh, RP Singh
A115: Indian Premier League | B115: 2009 | C115: N/A | D115: 39956 | E115: Johannesburg | F115: New Wanderers Stadium | G115: Royal Challengers Bangalore | H115: Chennai Super Kings | I115: Royal Challengers Bangalore | J115: field | K115: 149 | L115: 4 | M115: 146 | N115: 5 | O115: Royal Challengers Bangalore | P115: complete | Q115: 0 | R115: 6 | S115: MK Pandey | T115: J Srinath | U115: RE Koertzen | V115: SJA Taufel | W115: IL Howell | X115: KH Hurter | Y115: T20 | Z115: 20 | AA115: 6 | AB115: male | AC115: club | AD115: JH Kallis, MK Pandey, RE van der Merwe, R Dravid, V Kohli, LRPL Taylor, RV Uthappa, MV Boucher, P Kumar, R Vinay Kumar, A Kumble | AE115: PA Patel, ML Hayden, MS Dhoni, SK Raina, JA Morkel, JDP Oram, S Badrinath, SB Jakati, L Balaji, M Muralitharan, MS Gony
A116: Indian Premier League | B116: 2009 | C116: N/A | D116: 39957 | E116: Johannesburg | F116: New Wanderers Stadium | G116: Royal Challengers Bangalore | H116: Deccan Chargers | I116: Royal Challengers Bangalore | J116: field | K116: 137 | L116: 9 | M116: 143 | N116: 6 | O116: Deccan Chargers | P116: complete | Q116: 6 | R116: 0 | S116: A Kumble | T116: J Srinath | U116: RE Koertzen | V116: SJA Taufel | W116: DJ Harper | X116: ZTA Ndamane | Y116: T20 | Z116: 20 | AA116: 6 | AB116: male | AC116: club | AD116: JH Kallis, MK Pandey, RE van der Merwe, R Dravid, LRPL Taylor, V Kohli, MV Boucher, RV Uthappa, P Kumar, R Vinay Kumar, A Kumble | AE116: AC Gilchrist, HH Gibbs, TL Suman, A Symonds, RG Sharma, Y Venugopal Rao, AA Bilakhia, RJ Harris, PP Ojha, Harmeet Singh, RP Singh
A117: Indian Premier League | B117: 2009/10 | C117: 1 | D117: 40249 | E117: Mumbai | F117: Dr DY Patil Sports Academy | G117: Deccan Chargers | H117: Kolkata Knight Riders | I117: Deccan Chargers | J117: field | K117: 150 | L117: 7 | M117: 161 | N117: 4 | O117: Kolkata Knight Riders | P117: complete | Q117: 11 | R117: 0 | S117: AD Mathews | T117: AJ Pycroft | U117: RE Koertzen | V117: RB Tiffin | W117: BG Jerling | X117: SN Bandekar | Y117: T20 | Z117: 20 | AA117: 6 | AB117: male | AC117: club | AD117: AC Gilchrist, VVS Laxman, HH Gibbs, A Symonds, RG Sharma, Anirudh Singh, TL Suman, WPUJC Vaas, Jaskaran Singh, RP Singh, PP Ojha | AE117: MK Tiwary, BJ Hodge, SC Ganguly, CA Pujara, OA Shah, AD Mathews, WP Saha, LR Shukla, M Kartik, CK Langeveldt, I Sharma
A118: Indian Premier League | B118: 2009/10 | C118: 2 | D118: 40250 | E118: Mumbai | F118: Brabourne Stadium | G118: Mumbai Indians | H118: Rajasthan Royals | I118: Mumbai Indians | J118: bat | K118: 212 | L118: 7 | M118: 208 | N118: 7 | O118: Mumbai Indians | P118: complete | Q118: 4 | R118: 0 | S118: YK Pathan | T118: AJ Pycroft | U118: RE Koertzen | V118: RB Tiffin | W118: BG Jerling | X118: VM Bandiwadekar | Y118: T20 | Z118: 20 | AA118: 6 | AB118: male | AC118: club | AD118: ST Jayasuriya, SR Tendulkar, AP Tare, SS Tiwary, AT Rayudu, R Sathish, Harbhajan Singh, R McLaren, Z Khan, SL Malinga, AG Murtaza | AE118: GC Smith, SA Asnodkar, NV Ojha, AA Jhunjhunwala, YK Pathan, P Dogra, AD Mascarenhas, A Uniyal, SK Warne, Kamran Khan, SW Tait
A119: Indian Premier League | B119: 2009/10 | C119: 3 | D119: 40250 | E119: Chandigarh | F119: Punjab Cricket Association Stadium, Mohali | G119: Kings XI Punjab | H119: Delhi Daredevils | I119: Delhi Daredevils | J119: field | K119: 142 | L119: 9 | M119: 146 | N119: 5 | O119: Delhi Daredevils | P119: complete | Q119: 0 | R119: 5 | S119: G Gambhir | T119: S Venkataraghavan | U119: BR Doctrove | V119: S Ravi | W119: SK Tarapore | X119: C Shamshuddin | Y119: T20 | Z119: 20 | AA119: 6 | AB119: male | AC119: club | AD119: RS Bopara, MS Bisla, KC Sangakkara, Yuvraj Singh, DPMD Jayawardene, IK Pathan, M Kaif, PP Chawla, RR Powar, S Sreesanth, YA Abdulla | AE119: G Gambhir, V Sehwag, TM Dilshan, AB de Villiers, KD Karthik, M Manhas, MF Maharoof, A Mishra, PJ Sangwan, VY Mahesh, DP Nannes
A120: Indian Premier League | B120: 2009/10 | C120: 4 | D120: 40251 | E120: Kolkata | F120: Eden Gardens | G120: Kolkata Knight Riders | H120: Royal Challengers Bangalore | I120: Kolkata Knight Riders | J120: field | K120: 136 | L120: 3 | M120: 135 | N120: 7 | O120: Kolkata Knight Riders | P120: complete | Q120: 0 | R120: 7 | S120: MK Tiwary | T120: Yashpal Sharma | U120: HDPK Dharmasena | V120: AM Saheba | W120: M Erasmus | X120: R Shankar | Y120: T20 | Z120: 20 | AA120: 6 | AB120: male | AC120: club | AD120: BJ Hodge, MK Tiwary, SC Ganguly, CA Pujara, OA Shah, RS Gavaskar, AD Mathews, WP Saha, M Kartik, CK Langeveldt, I Sharma | AE120: JH Kallis, SP Goswami, MK Pandey, V Kohli, EJG Morgan, R Dravid, RV Uthappa, RE van der Merwe, P Kumar, A Kumble, DW Steyn
A121: Indian Premier League | B121: 2009/10 | C121: 5 | D121: 40251 | E121: Chennai | F121: MA Chidambaram Stadium, Chepauk | G121: Chennai Super Kings | H121: Deccan Chargers | I121: Deccan Chargers | J121: bat | K121: 159 | L121: 9 | M121: 190 | N121: 4 | O121: Deccan Chargers | P121: complete | Q121: 31 | R121: 0 | S121: WPUJC Vaas | T121: D Govindjee | U121: K Hariharan | V121: DJ Harper | W121: S Das | X121: J Madanagopal | Y121: T20 | Z121: 20 | AA121: 6 | AB121: male | AC121: club | AD121: M Vijay, ML Hayden, SK Raina, S Badrinath, JM Kemp, MS Dhoni, JA Morkel, R Ashwin, L Balaji, M Muralitharan, S Tyagi | AE121: AC Gilchrist, VVS Laxman, HH Gibbs, A Symonds, RG Sharma, TL Suman, Anirudh Singh, WPUJC Vaas, Jaskaran Singh, RP Singh, PP Ojha
A122: Indian Premier League | B122: 2009/10 | C122: 6 | D122: 40252 | E122: Ahmedabad | F122: Sardar Patel Stadium, Motera | G122: Rajasthan Royals | H122: Delhi Daredevils | I122: Delhi Daredevils | J122: field | K122: 141 | L122: 6 | M122: 142 | N122: 4 | O122: Delhi Daredevils | P122: complete | Q122: 0 | R122: 6 | S122: V Sehwag | T122: AJ Pycroft | U122: BG Jerling | V122: RE Koertzen | W122: RB Tiffin | X122: S Dua | Y122: T20 | Z122: 20 | AA122: 6 | AB122: male | AC122: club | AD122: SA Asnodkar, GC Smith, NV Ojha, YK Pathan, AA Jhunjhunwala, P Dogra, AD Mascarenhas, A Uniyal, SK Warne, SW Tait, MM Patel | AE122: G Gambhir, V Sehwag, TM Dilshan, AB de Villiers, KD Karthik, M Manhas, MF Maharoof, A Mishra, S Ladda, PJ Sangwan, DP Nannes
A123: Indian Premier League | B123: 2009/10 | C123: 7 | D123: 40253 | E123: Bangalore | F123: M Chinnaswamy Stadium | G123: Royal Challengers Bangalore | H123: Kings XI Punjab | I123: Kings XI Punjab | J123: bat | K123: 204 | L123: 2 | M123: 203 | N123: 3 | O123: Royal Challengers Bangalore | P123: complete | Q123: 0 | R123: 8 | S123: JH Kallis | T123: D Govindjee | U123: S Das | V123: DJ Harper | W123: K Hariharan | X123: KN Ananthapadmanabhan | Y123: T20 | Z123: 20 | AA123: 6 | AB123: male | AC123: club | AD123: MK Pandey, JH Kallis, RV Uthappa, V Kohli, R Dravid, EJG Morgan, MV Boucher, P Kumar, A Kumble, DW Steyn, R Vinay Kumar | AE123: RS Bopara, MS Bisla, Yuvraj Singh, DPMD Jayawardene, IK Pathan, KC Sangakkara, M Kaif, PP Chawla, Bipul Sharma, YA Abdulla, S Sreesanth
...

Sheet Aggregate functions
B5: Matches | C5: =COUNT(ipl_comprehensive_dataset!C2:C1244) -> 1169
B7: Total Runs | C7: =SUM(ipl_comprehensive_dataset!M:M,ipl_comprehensive_dataset!K:K) -> 401738 | E7: Team 1 | F7: =SUM(ipl_comprehensive_dataset!K:K) -> 206153
C8: =SUM(ipl_comprehensive_dataset!M1:M1244,ipl_comprehensive_dataset!K2:K1244) -> 401738 | E8: Team 2 | F8: =SUM(ipl_comprehensive_dataset!M:M) -> 195585 | H8: 12 | J8: count | K8: =COUNT(H8:H15) -> 3
H9: Surj
H10: 46419 | J10: counta | K10: =COUNTA(H8:H11,H12,H13,H14,H15) -> 6
H11: 20206
J12: countblank | K12: =COUNTBLANK(H8:H15) -> 2
B13: Region | C13: Sales (in Lakhs) | H13: =1/0 -> #DIV/0!
B14: North | C14: 23 | E14: sum | F14: =SUM(C14,C15,C16,C18,C19,C21,C22) -> 315 | K14: 2
B15: East | C15: 57 | E15: sum | F15: =SUM(C14:C22) -> 315 | H15: =1/0 -> #DIV/0!
B16: South | C16: 40 | E16: sum | F16: =SUM(C14,C16,C19,C22) -> 157
B17: West | C17: abc | E17: sum | F17: =SUM(C14:C16,C18:C19,C22) -> 243
B18: Central | C18: 29 | E18: avg | F18: =AVERAGE(C14:C22) -> 45 | J18: 1
B19: North-East | C19: 33 | E19: min | F19: =MIN(C14:C22) -> 23 | J19: 2
B20: South-West | E20: max | F20: =MAX(C14:C22) -> 72 | J20: 3
B21: South-Central | C21: 72 | E21: count | F21: =COUNT(C14:C22) -> 7 | J21: 3
B22: North-west | C22: 61 | E22: counta | F22: =COUNTA(C14:C22) -> 8 | J22: 4
E23: count blank | F23: =COUNTBLANK(C14:C22) -> 1 | H23: =COUNT(_xlfn.UNIQUE(J18:J22)) -> 4
E24: small | F24: =SMALL(C14:C22,2) -> 29
E25: large | F25: =LARGE(C14:C22,7) -> 23

Sheet IFs
B2: Emp Code | C2: Employee Name | D2: Address | E2: City | F2: Region | G2: Department | H2: Basic | J2: SUM | K2: =SUM(H3:H22) -> 184600 | L2: =_xlfn.FORMULATEXT(K2) -> =SUM(H3:H22) | M2: Q-1: Find total Salary Distributed.
B3: 7 | C3: Prakash Dutta | D3: Elgin Road | E3: Kolkata | F3: E | G3: Marketing | H3: 4500 | J3: AVERAGE | K3: =AVERAGE(H3:H22) -> 9230 | L3: =_xlfn.FORMULATEXT(K3) -> =AVERAGE(H3:H22) | M3: Q-2: Find Average Salary received by an employee
B4: 15 | C4: Prateek Babbar | D4: North Road | E4: Delhi | F4: N | G4: Marketing | H4: 4500 | J4: MAX | K4: =MAX(H3:H22) -> 16250 | L4: =_xlfn.FORMULATEXT(K4) -> =MAX(H3:H22) | M4: Q-3: Find MaximumSalary received by an employee
B5: 9 | C5: Arjun Jain | D5: MG Road | E5: Mumbai | F5: W | G5: Training | H5: 6250 | J5: MIN | K5: =MIN(H3:H22) -> 4500 | L5: =_xlfn.FORMULATEXT(K5) -> =MIN(H3:H22) | M5: Q-4: Find Minimum Salary received by an employee
B6: 17 | C6: Satish Puri | D6: Bandra | E6: Mumbai | F6: W | G6: Operation | H6: 6250 | J6: COUNT | K6: =COUNT(B3:B22) -> 20 | L6: =_xlfn.FORMULATEXT(K6) -> =COUNT(B3:B22) | M6: Q-5: Find total employees working
B7: 8 | C7: Manisha Guha | D7: Alipore | E7: Kolkata | F7: E | G7: R&D | H7: 6275 | J7: COUNTA | K7: =COUNTA(F3:F22) -> 20 | L7: =_xlfn.FORMULATEXT(K7) -> =COUNTA(F3:F22) | M7: Q-6: Find total regions
B8: 16 | C8: Sukanya Reddy | E8: Mangalore | F8: S | G8: R&D | H8: 6275 | J8: COUNtBLANK | K8: =COUNTBLANK(D3:D21) -> 3 | L8: =_xlfn.FORMULATEXT(K8) -> =COUNTBLANK(D3:D21) | M8: Q-7: Find number of missing sales
B9: 6 | C9: Jharna Biswal | D9: Link Road | E9: Cuttack | F9: E | G9: Accounts | H9: 6400 | J9: COUNTIF | K9: =COUNTIF(H3:H22,">10000") -> 7 | L9: =_xlfn.FORMULATEXT(K9) -> =COUNTIF(H3:H22,">10000") | M9: Q-8: Find count of salaries greater than 10k
B10: 14 | C10: Ashwini | D10: Sector 9 | E10: Mangalore | F10: S | G10: Accounts | H10: 6400 | J10: COUNTIF | K10: =COUNTIF(G3:G22,"=r&d") -> 5 | L10: =_xlfn.FORMULATEXT(K10) -> =COUNTIF(G3:G22,"=r&d") | M10: Q-9: Find number of employees working in R&D dept
B11: 10 | C11: Arjun Kapoor | E11: Bangalore | F11: S | G11: Accounts | H11: 8750 | J11: COUNTIF | K11: =COUNTIF(F3:F22,"=S") -> 7 | L11: =_xlfn.FORMULATEXT(K11) -> =COUNTIF(F3:F22,"=S") | M11: Q-10: Find number of employees from S Region
B12: 18 | C12: Anjum Chopra | D12: Worli | E12: Mumbai | F12: W | G12: R&D | H12: 8750 | J12: SUMIF | K12: =SUMIF(F3:F22,"=E",H3:H22) -> 17175 | L12: =_xlfn.FORMULATEXT(K12) -> =SUMIF(F3:F22,"=E",H3:H22) | M12: Q-11: Find total Salary distributed to E Region
B13: 1 | C13: JP Kumar | D13: Andheri (W) | E13: Mumbai | F13: W | G13: Training | H13: 10000 | J13: AVERAGEIF | K13: =AVERAGEIF(G3:G22,"Training",H3:H22) -> 11750 | L13: =_xlfn.FORMULATEXT(K13) -> =AVERAGEIF(G3:G22,"Training",H3:H22) | M13: Q-12: Find Average Salary received by Training Dept employees
B14: 12 | C14: Shahid Khan | D14: M.G Road | E14: Mangalore | F14: S | G14: R&D | H14: 10000 | J14: COUNTIF | K14: =COUNTIF(E3:E15,"Mumbai") -> 4 | L14: =_xlfn.FORMULATEXT(K14) -> =COUNTIF(E3:E15,"Mumbai") | M14: Q-13: Find count of employees from Mumbai City
B15: 20 | C15: Manish Grover | D15: L L R Road | E15: Noida | F15: N | G15: Training | H15: 10000
B16: 3 | C16: Priya Agarwal | D16: Sector 9 | F16: N | G16: Marketing | H16: 11250 | J16: SUMIFS | K16: =SUMIFS(H3:H22,G3:G22,"Training",F3:F22,"W") -> 16250 | L16: =_xlfn.FORMULATEXT(K16) -> =SUMIFS(H3:H22,G3:G22,"Training",F3:F22,"W") | M16: Q-1 Total Salary of Training Department Employees form W Region
B17: 11 | C17: Abrar | D17: Jayanagar | E17: Bangalore | F17: S | G17: Marketing | H17: 11250 | J17: AVERAGEIFS | K17: =AVERAGEIFS(H3:H22,G3:G22,"tRAINING",F3:F22,"w") -> 8125 | L17: =_xlfn.FORMULATEXT(K17) -> =AVERAGEIFS(H3:H22,G3:G22,"tRAINING",F3:F22,"w") | M17: Q-2 Average Salary of Training Department Employees form W Region
B18: 19 | C18: Akram Khan | D18: S P B Road | E18: Pune | F18: W | G18: Operation | H18: 11250 | J18: COUNTIFS | K18: =COUNTIFS(G3:G22,"training",F3:F22,"w") -> 2 | L18: =_xlfn.FORMULATEXT(K18) -> =COUNTIFS(G3:G22,"training",F3:F22,"w") | M18: Q-3 Total Number of Employees from Training Department and form W Region
B19: 2 | C19: Anjali Thakur | D19: Govindpuri | E19: Delhi | F19: N | G19: Accounts | H19: 12000 | J19: MAXIFS | K19: =_xlfn.MAXIFS(H3:H22,G3:G22,"training",F3:F22,"w") -> 10000 | L19: =_xlfn.FORMULATEXT(K19) -> =MAXIFS(H3:H22,G3:G22,"training",F3:F22,"w") | M19: Q-4 Max Salary of Employees from Training Department and form W Region
B20: 4 | C20: R Vasu | D20: Egmore | E20: Chennai | F20: S | G20: R&D | H20: 12000 | J20: MINIFS | K20: =_xlfn.MINIFS(H3:H22,G3:G22,G5,F3:F22,F5) -> 6250 | L20: =_xlfn.FORMULATEXT(K20) -> =MINIFS(H3:H22,G3:G22,G5,F3:F22,F5) | M20: Q-5 Min salary of Employees from Training Department and form W Region
B21: 5 | C21: Sanjay Gupta | E21: Delhi | F21: N | G21: Training | H21: 16250 | J21: SUMIFS | K21: =SUMIFS(H3:H22,G3:G22,G8,E3:E22,E8) -> 16275 | L21: =_xlfn.FORMULATEXT(K21) -> =SUMIFS(H3:H22,G3:G22,G8,E3:E22,E8) | M21: Q-6 Total Salary of R&D Department Employees from Manglore City
B22: 13 | C22: Anupam Mishra | D22: Govindpuri | E22: Mysore | F22: S | G22: Training | H22: 16250 | J22: COUNTIFS | K22: =COUNTIFS(H3:H22,">8000",H3:H22,"<12000") -> 8 | L22: =_xlfn.FORMULATEXT(K22) -> =COUNTIFS(H3:H22,">8000",H3:H22,"<12000") | M22: Q-7 Total Number of employees earning > 8000 and < 12000
M23: Q-7 Total Number of employees earning > 8000 and < 12000
J24: RANK
J25: RANK
I26: 2nd largest | J26: LARGE | K26: =LARGE(H3:H22,2) -> 16250 | L26: =_xlfn.FORMULATEXT(K26) -> =LARGE(H3:H22,2) | M26: using unique | N26: =LARGE(_xlfn.UNIQUE(H3:H22),2) -> 12000 | O26: =_xlfn.FORMULATEXT(N26) -> =LARGE(UNIQUE(H3:H22),2)
C27: 100 | D27: $100 | I27: 3rd smallest | J27: SMALL | K27: =SMALL(H3:H22,3) -> 6250 | L27: =_xlfn.FORMULATEXT(K27) -> =SMALL(H3:H22,3) | M27: using unique | N27: =SMALL(_xlfn.UNIQUE(H3:H22),3) -> 6275 | O27: =_xlfn.FORMULATEXT(N27) -> =SMALL(UNIQUE(H3:H22),3)
C28: 200 | D28: $200
C29: =SUM(C28,C27) -> 300 | D29: =SUM(D27,D28) -> 0
